[2021-05-16 20:26:44,470] {taskinstance.py:877} INFO - Dependencies all met for <TaskInstance: matches_links.get_rugby_pass_match_data 2021-04-22T10:00:00+00:00 [queued]>
[2021-05-16 20:26:44,475] {taskinstance.py:877} INFO - Dependencies all met for <TaskInstance: matches_links.get_rugby_pass_match_data 2021-04-22T10:00:00+00:00 [queued]>
[2021-05-16 20:26:44,475] {taskinstance.py:1068} INFO - 
--------------------------------------------------------------------------------
[2021-05-16 20:26:44,475] {taskinstance.py:1069} INFO - Starting attempt 1 of 2
[2021-05-16 20:26:44,475] {taskinstance.py:1070} INFO - 
--------------------------------------------------------------------------------
[2021-05-16 20:26:44,479] {taskinstance.py:1089} INFO - Executing <Task(PythonOperator): get_rugby_pass_match_data> on 2021-04-22T10:00:00+00:00
[2021-05-16 20:26:44,482] {standard_task_runner.py:52} INFO - Started process 28524 to run task
[2021-05-16 20:26:44,488] {standard_task_runner.py:76} INFO - Running: ['airflow', 'tasks', 'run', 'matches_links', 'get_rugby_pass_match_data', '2021-04-22T10:00:00+00:00', '--job-id', '5262', '--pool', 'default_pool', '--raw', '--subdir', 'DAGS_FOLDER/matches_links.py', '--cfg-path', '/var/folders/tp/ft4rfkmn1kz3dyw8hlfz1dxw0000gn/T/tmpejpl87ez', '--error-file', '/var/folders/tp/ft4rfkmn1kz3dyw8hlfz1dxw0000gn/T/tmpmt5wnxdw']
[2021-05-16 20:26:44,490] {standard_task_runner.py:77} INFO - Job 5262: Subtask get_rugby_pass_match_data
[2021-05-16 20:26:44,518] {logging_mixin.py:104} INFO - Running <TaskInstance: matches_links.get_rugby_pass_match_data 2021-04-22T10:00:00+00:00 [running]> on host Henrys-MacBook-Pro.local
[2021-05-16 20:26:44,538] {taskinstance.py:1281} INFO - Exporting the following env vars:
AIRFLOW_CTX_DAG_OWNER=me
AIRFLOW_CTX_DAG_ID=matches_links
AIRFLOW_CTX_TASK_ID=get_rugby_pass_match_data
AIRFLOW_CTX_EXECUTION_DATE=2021-04-22T10:00:00+00:00
AIRFLOW_CTX_DAG_RUN_ID=backfill__2021-04-22T10:00:00+00:00
[2021-05-16 20:26:44,546] {callbacks.py:123} WARNING - R[write to console]: Error in file(filename, "r", encoding = encoding) : 
  cannot open the connection

[2021-05-16 20:26:44,547] {callbacks.py:123} WARNING - R[write to console]: In addition: 
[2021-05-16 20:26:44,547] {callbacks.py:123} WARNING - R[write to console]: Warning message:

[2021-05-16 20:26:44,547] {callbacks.py:123} WARNING - R[write to console]: In file(filename, "r", encoding = encoding) :
[2021-05-16 20:26:44,548] {callbacks.py:123} WARNING - R[write to console]: 
 
[2021-05-16 20:26:44,548] {callbacks.py:123} WARNING - R[write to console]:  cannot open file 'Users/harry/rugby_data_project_airflow/R/scripts/create_matches_table.R': No such file or directory

[2021-05-16 20:26:44,554] {taskinstance.py:1482} ERROR - Task failed with exception
Traceback (most recent call last):
  File "/Users/harry/.local/share/virtualenvs/rugby_data_project_airflow-d2RAFQI6/lib/python3.8/site-packages/airflow/models/taskinstance.py", line 1138, in _run_raw_task
    self._prepare_and_execute_task_with_callbacks(context, task)
  File "/Users/harry/.local/share/virtualenvs/rugby_data_project_airflow-d2RAFQI6/lib/python3.8/site-packages/airflow/models/taskinstance.py", line 1311, in _prepare_and_execute_task_with_callbacks
    result = self._execute_task(context, task_copy)
  File "/Users/harry/.local/share/virtualenvs/rugby_data_project_airflow-d2RAFQI6/lib/python3.8/site-packages/airflow/models/taskinstance.py", line 1341, in _execute_task
    result = task_copy.execute(context=context)
  File "/Users/harry/.local/share/virtualenvs/rugby_data_project_airflow-d2RAFQI6/lib/python3.8/site-packages/airflow/operators/python.py", line 117, in execute
    return_value = self.execute_callable()
  File "/Users/harry/.local/share/virtualenvs/rugby_data_project_airflow-d2RAFQI6/lib/python3.8/site-packages/airflow/operators/python.py", line 128, in execute_callable
    return self.python_callable(*self.op_args, **self.op_kwargs)
  File "/Users/harry/rugby_data_project_airflow/airflow/dags/matches_links.py", line 10, in run_r
    r['source']("Users/harry/rugby_data_project_airflow/R/scripts/create_matches_table.R")
  File "/Users/harry/.local/share/virtualenvs/rugby_data_project_airflow-d2RAFQI6/lib/python3.8/site-packages/rpy2/robjects/functions.py", line 198, in __call__
    return (super(SignatureTranslatedFunction, self)
  File "/Users/harry/.local/share/virtualenvs/rugby_data_project_airflow-d2RAFQI6/lib/python3.8/site-packages/rpy2/robjects/functions.py", line 125, in __call__
    res = super(Function, self).__call__(*new_args, **new_kwargs)
  File "/Users/harry/.local/share/virtualenvs/rugby_data_project_airflow-d2RAFQI6/lib/python3.8/site-packages/rpy2/rinterface_lib/conversion.py", line 45, in _
    cdata = function(*args, **kwargs)
  File "/Users/harry/.local/share/virtualenvs/rugby_data_project_airflow-d2RAFQI6/lib/python3.8/site-packages/rpy2/rinterface.py", line 680, in __call__
    raise embedded.RRuntimeError(_rinterface._geterrmessage())
rpy2.rinterface_lib.embedded.RRuntimeError: Error in file(filename, "r", encoding = encoding) : 
  cannot open the connection

[2021-05-16 20:26:44,561] {taskinstance.py:1525} INFO - Marking task as UP_FOR_RETRY. dag_id=matches_links, task_id=get_rugby_pass_match_data, execution_date=20210422T100000, start_date=20210516T192644, end_date=20210516T192644
[2021-05-16 20:26:44,592] {local_task_job.py:146} INFO - Task exited with return code 1
[2021-05-16 20:30:48,038] {taskinstance.py:877} INFO - Dependencies all met for <TaskInstance: matches_links.get_rugby_pass_match_data 2021-04-22T10:00:00+00:00 [queued]>
[2021-05-16 20:30:48,042] {taskinstance.py:877} INFO - Dependencies all met for <TaskInstance: matches_links.get_rugby_pass_match_data 2021-04-22T10:00:00+00:00 [queued]>
[2021-05-16 20:30:48,042] {taskinstance.py:1068} INFO - 
--------------------------------------------------------------------------------
[2021-05-16 20:30:48,043] {taskinstance.py:1069} INFO - Starting attempt 1 of 2
[2021-05-16 20:30:48,043] {taskinstance.py:1070} INFO - 
--------------------------------------------------------------------------------
[2021-05-16 20:30:48,048] {taskinstance.py:1089} INFO - Executing <Task(PythonOperator): get_rugby_pass_match_data> on 2021-04-22T10:00:00+00:00
[2021-05-16 20:30:48,049] {standard_task_runner.py:52} INFO - Started process 31198 to run task
[2021-05-16 20:30:48,057] {standard_task_runner.py:76} INFO - Running: ['airflow', 'tasks', 'run', 'matches_links', 'get_rugby_pass_match_data', '2021-04-22T10:00:00+00:00', '--job-id', '5263', '--pool', 'default_pool', '--raw', '--subdir', 'DAGS_FOLDER/matches_links/matches_links.py', '--cfg-path', '/var/folders/tp/ft4rfkmn1kz3dyw8hlfz1dxw0000gn/T/tmp_4diwa4m', '--error-file', '/var/folders/tp/ft4rfkmn1kz3dyw8hlfz1dxw0000gn/T/tmp378lte3q']
[2021-05-16 20:30:48,058] {standard_task_runner.py:77} INFO - Job 5263: Subtask get_rugby_pass_match_data
[2021-05-16 20:30:48,088] {logging_mixin.py:104} INFO - Running <TaskInstance: matches_links.get_rugby_pass_match_data 2021-04-22T10:00:00+00:00 [running]> on host Henrys-MacBook-Pro.local
[2021-05-16 20:30:48,109] {taskinstance.py:1281} INFO - Exporting the following env vars:
AIRFLOW_CTX_DAG_OWNER=me
AIRFLOW_CTX_DAG_ID=matches_links
AIRFLOW_CTX_TASK_ID=get_rugby_pass_match_data
AIRFLOW_CTX_EXECUTION_DATE=2021-04-22T10:00:00+00:00
AIRFLOW_CTX_DAG_RUN_ID=backfill__2021-04-22T10:00:00+00:00
[2021-05-16 20:30:48,115] {callbacks.py:123} WARNING - R[write to console]: Error in file(filename, "r", encoding = encoding) : 
  cannot open the connection

[2021-05-16 20:30:48,116] {callbacks.py:123} WARNING - R[write to console]: In addition: 
[2021-05-16 20:30:48,116] {callbacks.py:123} WARNING - R[write to console]: Warning message:

[2021-05-16 20:30:48,116] {callbacks.py:123} WARNING - R[write to console]: In file(filename, "r", encoding = encoding) :
[2021-05-16 20:30:48,117] {callbacks.py:123} WARNING - R[write to console]: 
 
[2021-05-16 20:30:48,117] {callbacks.py:123} WARNING - R[write to console]:  cannot open file 'Users/harry/rugby_data_project_airflow/R/scripts/create_matches_table.R': No such file or directory

[2021-05-16 20:30:48,121] {taskinstance.py:1482} ERROR - Task failed with exception
Traceback (most recent call last):
  File "/Users/harry/.local/share/virtualenvs/rugby_data_project_airflow-d2RAFQI6/lib/python3.8/site-packages/airflow/models/taskinstance.py", line 1138, in _run_raw_task
    self._prepare_and_execute_task_with_callbacks(context, task)
  File "/Users/harry/.local/share/virtualenvs/rugby_data_project_airflow-d2RAFQI6/lib/python3.8/site-packages/airflow/models/taskinstance.py", line 1311, in _prepare_and_execute_task_with_callbacks
    result = self._execute_task(context, task_copy)
  File "/Users/harry/.local/share/virtualenvs/rugby_data_project_airflow-d2RAFQI6/lib/python3.8/site-packages/airflow/models/taskinstance.py", line 1341, in _execute_task
    result = task_copy.execute(context=context)
  File "/Users/harry/.local/share/virtualenvs/rugby_data_project_airflow-d2RAFQI6/lib/python3.8/site-packages/airflow/operators/python.py", line 117, in execute
    return_value = self.execute_callable()
  File "/Users/harry/.local/share/virtualenvs/rugby_data_project_airflow-d2RAFQI6/lib/python3.8/site-packages/airflow/operators/python.py", line 128, in execute_callable
    return self.python_callable(*self.op_args, **self.op_kwargs)
  File "/Users/harry/rugby_data_project_airflow/airflow/dags/matches_links/matches_links.py", line 10, in run_r
    r['source']("Users/harry/rugby_data_project_airflow/R/scripts/create_matches_table.R")
  File "/Users/harry/.local/share/virtualenvs/rugby_data_project_airflow-d2RAFQI6/lib/python3.8/site-packages/rpy2/robjects/functions.py", line 198, in __call__
    return (super(SignatureTranslatedFunction, self)
  File "/Users/harry/.local/share/virtualenvs/rugby_data_project_airflow-d2RAFQI6/lib/python3.8/site-packages/rpy2/robjects/functions.py", line 125, in __call__
    res = super(Function, self).__call__(*new_args, **new_kwargs)
  File "/Users/harry/.local/share/virtualenvs/rugby_data_project_airflow-d2RAFQI6/lib/python3.8/site-packages/rpy2/rinterface_lib/conversion.py", line 45, in _
    cdata = function(*args, **kwargs)
  File "/Users/harry/.local/share/virtualenvs/rugby_data_project_airflow-d2RAFQI6/lib/python3.8/site-packages/rpy2/rinterface.py", line 680, in __call__
    raise embedded.RRuntimeError(_rinterface._geterrmessage())
rpy2.rinterface_lib.embedded.RRuntimeError: Error in file(filename, "r", encoding = encoding) : 
  cannot open the connection

[2021-05-16 20:30:48,126] {taskinstance.py:1525} INFO - Marking task as UP_FOR_RETRY. dag_id=matches_links, task_id=get_rugby_pass_match_data, execution_date=20210422T100000, start_date=20210516T193048, end_date=20210516T193048
[2021-05-16 20:30:48,160] {local_task_job.py:146} INFO - Task exited with return code 1
[2021-05-16 20:32:28,202] {taskinstance.py:877} INFO - Dependencies all met for <TaskInstance: matches_links.get_rugby_pass_match_data 2021-04-22T10:00:00+00:00 [queued]>
[2021-05-16 20:32:28,208] {taskinstance.py:877} INFO - Dependencies all met for <TaskInstance: matches_links.get_rugby_pass_match_data 2021-04-22T10:00:00+00:00 [queued]>
[2021-05-16 20:32:28,208] {taskinstance.py:1068} INFO - 
--------------------------------------------------------------------------------
[2021-05-16 20:32:28,208] {taskinstance.py:1069} INFO - Starting attempt 1 of 2
[2021-05-16 20:32:28,208] {taskinstance.py:1070} INFO - 
--------------------------------------------------------------------------------
[2021-05-16 20:32:28,212] {taskinstance.py:1089} INFO - Executing <Task(PythonOperator): get_rugby_pass_match_data> on 2021-04-22T10:00:00+00:00
[2021-05-16 20:32:28,214] {standard_task_runner.py:52} INFO - Started process 32314 to run task
[2021-05-16 20:32:28,221] {standard_task_runner.py:76} INFO - Running: ['airflow', 'tasks', 'run', 'matches_links', 'get_rugby_pass_match_data', '2021-04-22T10:00:00+00:00', '--job-id', '3', '--pool', 'default_pool', '--raw', '--subdir', 'DAGS_FOLDER/matches_links/matches_links.py', '--cfg-path', '/var/folders/tp/ft4rfkmn1kz3dyw8hlfz1dxw0000gn/T/tmpu1k1rkok', '--error-file', '/var/folders/tp/ft4rfkmn1kz3dyw8hlfz1dxw0000gn/T/tmpag2auqxg']
[2021-05-16 20:32:28,222] {standard_task_runner.py:77} INFO - Job 3: Subtask get_rugby_pass_match_data
[2021-05-16 20:32:28,261] {logging_mixin.py:104} INFO - Running <TaskInstance: matches_links.get_rugby_pass_match_data 2021-04-22T10:00:00+00:00 [running]> on host Henrys-MacBook-Pro.local
[2021-05-16 20:32:28,292] {taskinstance.py:1281} INFO - Exporting the following env vars:
AIRFLOW_CTX_DAG_OWNER=me
AIRFLOW_CTX_DAG_ID=matches_links
AIRFLOW_CTX_TASK_ID=get_rugby_pass_match_data
AIRFLOW_CTX_EXECUTION_DATE=2021-04-22T10:00:00+00:00
AIRFLOW_CTX_DAG_RUN_ID=backfill__2021-04-22T10:00:00+00:00
[2021-05-16 20:32:28,301] {callbacks.py:123} WARNING - R[write to console]: Error in file(filename, "r", encoding = encoding) : 
  cannot open the connection

[2021-05-16 20:32:28,301] {callbacks.py:123} WARNING - R[write to console]: In addition: 
[2021-05-16 20:32:28,302] {callbacks.py:123} WARNING - R[write to console]: Warning message:

[2021-05-16 20:32:28,302] {callbacks.py:123} WARNING - R[write to console]: In file(filename, "r", encoding = encoding) :
[2021-05-16 20:32:28,303] {callbacks.py:123} WARNING - R[write to console]: 
 
[2021-05-16 20:32:28,303] {callbacks.py:123} WARNING - R[write to console]:  cannot open file 'create_matches_table.R': No such file or directory

[2021-05-16 20:32:28,308] {taskinstance.py:1482} ERROR - Task failed with exception
Traceback (most recent call last):
  File "/Users/harry/.local/share/virtualenvs/rugby_data_project_airflow-d2RAFQI6/lib/python3.8/site-packages/airflow/models/taskinstance.py", line 1138, in _run_raw_task
    self._prepare_and_execute_task_with_callbacks(context, task)
  File "/Users/harry/.local/share/virtualenvs/rugby_data_project_airflow-d2RAFQI6/lib/python3.8/site-packages/airflow/models/taskinstance.py", line 1311, in _prepare_and_execute_task_with_callbacks
    result = self._execute_task(context, task_copy)
  File "/Users/harry/.local/share/virtualenvs/rugby_data_project_airflow-d2RAFQI6/lib/python3.8/site-packages/airflow/models/taskinstance.py", line 1341, in _execute_task
    result = task_copy.execute(context=context)
  File "/Users/harry/.local/share/virtualenvs/rugby_data_project_airflow-d2RAFQI6/lib/python3.8/site-packages/airflow/operators/python.py", line 117, in execute
    return_value = self.execute_callable()
  File "/Users/harry/.local/share/virtualenvs/rugby_data_project_airflow-d2RAFQI6/lib/python3.8/site-packages/airflow/operators/python.py", line 128, in execute_callable
    return self.python_callable(*self.op_args, **self.op_kwargs)
  File "/Users/harry/rugby_data_project_airflow/airflow/dags/matches_links/matches_links.py", line 11, in run_r
    r['source']("create_matches_table.R")
  File "/Users/harry/.local/share/virtualenvs/rugby_data_project_airflow-d2RAFQI6/lib/python3.8/site-packages/rpy2/robjects/functions.py", line 198, in __call__
    return (super(SignatureTranslatedFunction, self)
  File "/Users/harry/.local/share/virtualenvs/rugby_data_project_airflow-d2RAFQI6/lib/python3.8/site-packages/rpy2/robjects/functions.py", line 125, in __call__
    res = super(Function, self).__call__(*new_args, **new_kwargs)
  File "/Users/harry/.local/share/virtualenvs/rugby_data_project_airflow-d2RAFQI6/lib/python3.8/site-packages/rpy2/rinterface_lib/conversion.py", line 45, in _
    cdata = function(*args, **kwargs)
  File "/Users/harry/.local/share/virtualenvs/rugby_data_project_airflow-d2RAFQI6/lib/python3.8/site-packages/rpy2/rinterface.py", line 680, in __call__
    raise embedded.RRuntimeError(_rinterface._geterrmessage())
rpy2.rinterface_lib.embedded.RRuntimeError: Error in file(filename, "r", encoding = encoding) : 
  cannot open the connection

[2021-05-16 20:32:28,317] {taskinstance.py:1525} INFO - Marking task as UP_FOR_RETRY. dag_id=matches_links, task_id=get_rugby_pass_match_data, execution_date=20210422T100000, start_date=20210516T193228, end_date=20210516T193228
[2021-05-16 20:32:28,366] {local_task_job.py:146} INFO - Task exited with return code 1
[2021-05-16 20:48:03,520] {taskinstance.py:877} INFO - Dependencies all met for <TaskInstance: matches_links.get_rugby_pass_match_data 2021-04-22T10:00:00+00:00 [queued]>
[2021-05-16 20:48:03,526] {taskinstance.py:877} INFO - Dependencies all met for <TaskInstance: matches_links.get_rugby_pass_match_data 2021-04-22T10:00:00+00:00 [queued]>
[2021-05-16 20:48:03,526] {taskinstance.py:1068} INFO - 
--------------------------------------------------------------------------------
[2021-05-16 20:48:03,526] {taskinstance.py:1069} INFO - Starting attempt 1 of 2
[2021-05-16 20:48:03,526] {taskinstance.py:1070} INFO - 
--------------------------------------------------------------------------------
[2021-05-16 20:48:03,530] {taskinstance.py:1089} INFO - Executing <Task(PythonOperator): get_rugby_pass_match_data> on 2021-04-22T10:00:00+00:00
[2021-05-16 20:48:03,532] {standard_task_runner.py:52} INFO - Started process 43813 to run task
[2021-05-16 20:48:03,542] {standard_task_runner.py:76} INFO - Running: ['airflow', 'tasks', 'run', 'matches_links', 'get_rugby_pass_match_data', '2021-04-22T10:00:00+00:00', '--job-id', '4', '--pool', 'default_pool', '--raw', '--subdir', 'DAGS_FOLDER/matches_links/matches_links.py', '--cfg-path', '/var/folders/tp/ft4rfkmn1kz3dyw8hlfz1dxw0000gn/T/tmpfom77y0x', '--error-file', '/var/folders/tp/ft4rfkmn1kz3dyw8hlfz1dxw0000gn/T/tmphqi3uvu7']
[2021-05-16 20:48:03,543] {standard_task_runner.py:77} INFO - Job 4: Subtask get_rugby_pass_match_data
[2021-05-16 20:48:03,574] {logging_mixin.py:104} INFO - Running <TaskInstance: matches_links.get_rugby_pass_match_data 2021-04-22T10:00:00+00:00 [running]> on host 1.0.0.127.in-addr.arpa
[2021-05-16 20:48:03,596] {taskinstance.py:1281} INFO - Exporting the following env vars:
AIRFLOW_CTX_DAG_OWNER=me
AIRFLOW_CTX_DAG_ID=matches_links
AIRFLOW_CTX_TASK_ID=get_rugby_pass_match_data
AIRFLOW_CTX_EXECUTION_DATE=2021-04-22T10:00:00+00:00
AIRFLOW_CTX_DAG_RUN_ID=backfill__2021-04-22T10:00:00+00:00
[2021-05-16 20:48:03,607] {callbacks.py:123} WARNING - R[write to console]: Error in (function (file, local = FALSE, echo = verbose, print.eval = echo,  : 
  airflow/dags/matches_links/matches_links.py:1:8: unexpected symbol
1: import datetime
           ^

[2021-05-16 20:48:03,611] {taskinstance.py:1482} ERROR - Task failed with exception
Traceback (most recent call last):
  File "/Users/harry/.local/share/virtualenvs/rugby_data_project_airflow-d2RAFQI6/lib/python3.8/site-packages/airflow/models/taskinstance.py", line 1138, in _run_raw_task
    self._prepare_and_execute_task_with_callbacks(context, task)
  File "/Users/harry/.local/share/virtualenvs/rugby_data_project_airflow-d2RAFQI6/lib/python3.8/site-packages/airflow/models/taskinstance.py", line 1311, in _prepare_and_execute_task_with_callbacks
    result = self._execute_task(context, task_copy)
  File "/Users/harry/.local/share/virtualenvs/rugby_data_project_airflow-d2RAFQI6/lib/python3.8/site-packages/airflow/models/taskinstance.py", line 1341, in _execute_task
    result = task_copy.execute(context=context)
  File "/Users/harry/.local/share/virtualenvs/rugby_data_project_airflow-d2RAFQI6/lib/python3.8/site-packages/airflow/operators/python.py", line 117, in execute
    return_value = self.execute_callable()
  File "/Users/harry/.local/share/virtualenvs/rugby_data_project_airflow-d2RAFQI6/lib/python3.8/site-packages/airflow/operators/python.py", line 128, in execute_callable
    return self.python_callable(*self.op_args, **self.op_kwargs)
  File "/Users/harry/rugby_data_project_airflow/airflow/dags/matches_links/matches_links.py", line 11, in run_r
    r["source"]("airflow/dags/matches_links/matches_links.py")
  File "/Users/harry/.local/share/virtualenvs/rugby_data_project_airflow-d2RAFQI6/lib/python3.8/site-packages/rpy2/robjects/functions.py", line 198, in __call__
    return (super(SignatureTranslatedFunction, self)
  File "/Users/harry/.local/share/virtualenvs/rugby_data_project_airflow-d2RAFQI6/lib/python3.8/site-packages/rpy2/robjects/functions.py", line 125, in __call__
    res = super(Function, self).__call__(*new_args, **new_kwargs)
  File "/Users/harry/.local/share/virtualenvs/rugby_data_project_airflow-d2RAFQI6/lib/python3.8/site-packages/rpy2/rinterface_lib/conversion.py", line 45, in _
    cdata = function(*args, **kwargs)
  File "/Users/harry/.local/share/virtualenvs/rugby_data_project_airflow-d2RAFQI6/lib/python3.8/site-packages/rpy2/rinterface.py", line 680, in __call__
    raise embedded.RRuntimeError(_rinterface._geterrmessage())
rpy2.rinterface_lib.embedded.RRuntimeError: Error in (function (file, local = FALSE, echo = verbose, print.eval = echo,  : 
  airflow/dags/matches_links/matches_links.py:1:8: unexpected symbol
1: import datetime
           ^

[2021-05-16 20:48:03,619] {taskinstance.py:1525} INFO - Marking task as UP_FOR_RETRY. dag_id=matches_links, task_id=get_rugby_pass_match_data, execution_date=20210422T100000, start_date=20210516T194803, end_date=20210516T194803
[2021-05-16 20:48:03,632] {local_task_job.py:146} INFO - Task exited with return code 1
[2021-05-16 20:50:29,949] {taskinstance.py:877} INFO - Dependencies all met for <TaskInstance: matches_links.get_rugby_pass_match_data 2021-04-22T10:00:00+00:00 [queued]>
[2021-05-16 20:50:29,954] {taskinstance.py:877} INFO - Dependencies all met for <TaskInstance: matches_links.get_rugby_pass_match_data 2021-04-22T10:00:00+00:00 [queued]>
[2021-05-16 20:50:29,954] {taskinstance.py:1068} INFO - 
--------------------------------------------------------------------------------
[2021-05-16 20:50:29,954] {taskinstance.py:1069} INFO - Starting attempt 1 of 2
[2021-05-16 20:50:29,954] {taskinstance.py:1070} INFO - 
--------------------------------------------------------------------------------
[2021-05-16 20:50:29,959] {taskinstance.py:1089} INFO - Executing <Task(PythonOperator): get_rugby_pass_match_data> on 2021-04-22T10:00:00+00:00
[2021-05-16 20:50:29,961] {standard_task_runner.py:52} INFO - Started process 45400 to run task
[2021-05-16 20:50:29,967] {standard_task_runner.py:76} INFO - Running: ['airflow', 'tasks', 'run', 'matches_links', 'get_rugby_pass_match_data', '2021-04-22T10:00:00+00:00', '--job-id', '4', '--pool', 'default_pool', '--raw', '--subdir', 'DAGS_FOLDER/matches_links/matches_links.py', '--cfg-path', '/var/folders/tp/ft4rfkmn1kz3dyw8hlfz1dxw0000gn/T/tmpa_l7ns8y', '--error-file', '/var/folders/tp/ft4rfkmn1kz3dyw8hlfz1dxw0000gn/T/tmpgdgmc6ht']
[2021-05-16 20:50:29,968] {standard_task_runner.py:77} INFO - Job 4: Subtask get_rugby_pass_match_data
[2021-05-16 20:50:29,997] {logging_mixin.py:104} INFO - Running <TaskInstance: matches_links.get_rugby_pass_match_data 2021-04-22T10:00:00+00:00 [running]> on host 1.0.0.127.in-addr.arpa
[2021-05-16 20:50:30,020] {taskinstance.py:1281} INFO - Exporting the following env vars:
AIRFLOW_CTX_DAG_OWNER=me
AIRFLOW_CTX_DAG_ID=matches_links
AIRFLOW_CTX_TASK_ID=get_rugby_pass_match_data
AIRFLOW_CTX_EXECUTION_DATE=2021-04-22T10:00:00+00:00
AIRFLOW_CTX_DAG_RUN_ID=backfill__2021-04-22T10:00:00+00:00
[2021-05-16 20:50:32,161] {callbacks.py:123} WARNING - R[write to console]: ── [1mAttaching packages[22m ──────────────────────────────────────────────────────────────────────────────────────────────────────────────────────────────────────────────────────────────────────────────────────── tidyverse 1.3.0 ──

[2021-05-16 20:50:32,172] {callbacks.py:123} WARNING - R[write to console]: [32m✔[39m [34mggplot2[39m 3.3.3     [32m✔[39m [34mpurrr  [39m 0.3.3
[32m✔[39m [34mtibble [39m 3.0.4     [32m✔[39m [34mdplyr  [39m 1.0.2
[32m✔[39m [34mtidyr  [39m 1.1.2     [32m✔[39m [34mstringr[39m 1.4.0
[32m✔[39m [34mreadr  [39m 1.3.1     [32m✔[39m [34mforcats[39m 0.5.0

[2021-05-16 20:50:32,274] {callbacks.py:123} WARNING - R[write to console]: ── [1mConflicts[22m ─────────────────────────────────────────────────────────────────────────────────────────────────────────────────────────────────────────────────────────────────────────────────────────── tidyverse_conflicts() ──
[31m✖[39m [34mdplyr[39m::[32mfilter()[39m masks [34mstats[39m::filter()
[31m✖[39m [34mdplyr[39m::[32mlag()[39m    masks [34mstats[39m::lag()

[2021-05-16 20:50:32,281] {callbacks.py:123} WARNING - R[write to console]: 
Attaching package: ‘lubridate’


[2021-05-16 20:50:32,284] {callbacks.py:123} WARNING - R[write to console]: The following objects are masked from ‘package:base’:

    date, intersect, setdiff, union


[2021-05-16 20:50:32,290] {callbacks.py:123} WARNING - R[write to console]: Loading required package: xml2

[2021-05-16 20:50:32,302] {callbacks.py:123} WARNING - R[write to console]: 
Attaching package: ‘rvest’


[2021-05-16 20:50:32,303] {callbacks.py:123} WARNING - R[write to console]: The following object is masked from ‘package:purrr’:

    pluck


[2021-05-16 20:50:32,304] {callbacks.py:123} WARNING - R[write to console]: The following object is masked from ‘package:readr’:

    guess_encoding


[2021-05-16 20:50:32,342] {logging_mixin.py:104} INFO - [1]
[2021-05-16 20:50:32,342] {logging_mixin.py:104} INFO -  "Getting autumn_nations_cup links"
[2021-05-16 20:50:32,342] {logging_mixin.py:104} INFO - 
[2021-05-16 20:50:34,873] {logging_mixin.py:104} INFO - [1]
[2021-05-16 20:50:34,874] {logging_mixin.py:104} INFO -  "autumn_nations_cup saved"
[2021-05-16 20:50:34,874] {logging_mixin.py:104} INFO - 
[2021-05-16 20:50:34,874] {logging_mixin.py:104} INFO - [1]
[2021-05-16 20:50:34,875] {logging_mixin.py:104} INFO -  "Getting premiership links"
[2021-05-16 20:50:34,875] {logging_mixin.py:104} INFO - 
[2021-05-16 20:51:10,358] {local_task_job.py:174} WARNING - The recorded hostname 1.0.0.127.in-addr.arpa does not match this instance's hostname henrys-macbook-pro.local
[2021-05-16 20:51:10,372] {process_utils.py:100} INFO - Sending Signals.SIGTERM to GPID 45400
[2021-05-16 20:51:10,478] {taskinstance.py:1265} ERROR - Received SIGTERM. Terminating subprocesses.
[2021-05-16 20:51:10,480] {callbacks.py:280} ERROR - R[processevents]: Task received SIGTERM signal
[2021-05-16 20:52:10,414] {process_utils.py:113} WARNING - process psutil.Process(pid=45400, name='python3.8', status='running', started='20:50:29') did not respond to SIGTERM. Trying SIGKILL
[2021-05-16 20:52:10,447] {process_utils.py:66} INFO - Process psutil.Process(pid=45400, name='python3.8', status='terminated', exitcode=<Negsignal.SIGKILL: -9>, started='20:50:29') (45400) terminated with exit code Negsignal.SIGKILL
[2021-05-16 20:52:10,447] {standard_task_runner.py:128} ERROR - Job 4 was killed before it finished (likely due to running out of memory)
[2021-05-16 20:54:37,439] {taskinstance.py:877} INFO - Dependencies all met for <TaskInstance: matches_links.get_rugby_pass_match_data 2021-04-22T10:00:00+00:00 [queued]>
[2021-05-16 20:54:37,444] {taskinstance.py:877} INFO - Dependencies all met for <TaskInstance: matches_links.get_rugby_pass_match_data 2021-04-22T10:00:00+00:00 [queued]>
[2021-05-16 20:54:37,444] {taskinstance.py:1068} INFO - 
--------------------------------------------------------------------------------
[2021-05-16 20:54:37,444] {taskinstance.py:1069} INFO - Starting attempt 1 of 2
[2021-05-16 20:54:37,444] {taskinstance.py:1070} INFO - 
--------------------------------------------------------------------------------
[2021-05-16 20:54:37,450] {taskinstance.py:1089} INFO - Executing <Task(PythonOperator): get_rugby_pass_match_data> on 2021-04-22T10:00:00+00:00
[2021-05-16 20:54:37,451] {standard_task_runner.py:52} INFO - Started process 47955 to run task
[2021-05-16 20:54:37,458] {standard_task_runner.py:76} INFO - Running: ['airflow', 'tasks', 'run', 'matches_links', 'get_rugby_pass_match_data', '2021-04-22T10:00:00+00:00', '--job-id', '8', '--pool', 'default_pool', '--raw', '--subdir', 'DAGS_FOLDER/matches_links/matches_links.py', '--cfg-path', '/var/folders/tp/ft4rfkmn1kz3dyw8hlfz1dxw0000gn/T/tmpaldtp4pp', '--error-file', '/var/folders/tp/ft4rfkmn1kz3dyw8hlfz1dxw0000gn/T/tmpmr4twg2_']
[2021-05-16 20:54:37,459] {standard_task_runner.py:77} INFO - Job 8: Subtask get_rugby_pass_match_data
[2021-05-16 20:54:37,489] {logging_mixin.py:104} INFO - Running <TaskInstance: matches_links.get_rugby_pass_match_data 2021-04-22T10:00:00+00:00 [running]> on host 1.0.0.127.in-addr.arpa
[2021-05-16 20:54:37,510] {taskinstance.py:1281} INFO - Exporting the following env vars:
AIRFLOW_CTX_DAG_OWNER=me
AIRFLOW_CTX_DAG_ID=matches_links
AIRFLOW_CTX_TASK_ID=get_rugby_pass_match_data
AIRFLOW_CTX_EXECUTION_DATE=2021-04-22T10:00:00+00:00
AIRFLOW_CTX_DAG_RUN_ID=backfill__2021-04-22T10:00:00+00:00
[2021-05-16 20:54:37,511] {taskinstance.py:1482} ERROR - Task failed with exception
Traceback (most recent call last):
  File "/Users/harry/.local/share/virtualenvs/rugby_data_project_airflow-d2RAFQI6/lib/python3.8/site-packages/airflow/models/taskinstance.py", line 1138, in _run_raw_task
    self._prepare_and_execute_task_with_callbacks(context, task)
  File "/Users/harry/.local/share/virtualenvs/rugby_data_project_airflow-d2RAFQI6/lib/python3.8/site-packages/airflow/models/taskinstance.py", line 1311, in _prepare_and_execute_task_with_callbacks
    result = self._execute_task(context, task_copy)
  File "/Users/harry/.local/share/virtualenvs/rugby_data_project_airflow-d2RAFQI6/lib/python3.8/site-packages/airflow/models/taskinstance.py", line 1341, in _execute_task
    result = task_copy.execute(context=context)
  File "/Users/harry/.local/share/virtualenvs/rugby_data_project_airflow-d2RAFQI6/lib/python3.8/site-packages/airflow/operators/python.py", line 112, in execute
    context.update(self.op_kwargs)
ValueError: dictionary update sequence element #0 has length 1; 2 is required
[2021-05-16 20:54:37,512] {taskinstance.py:1525} INFO - Marking task as UP_FOR_RETRY. dag_id=matches_links, task_id=get_rugby_pass_match_data, execution_date=20210422T100000, start_date=20210516T195437, end_date=20210516T195437
[2021-05-16 20:54:37,561] {local_task_job.py:146} INFO - Task exited with return code 1
[2021-05-16 21:03:53,159] {taskinstance.py:877} INFO - Dependencies all met for <TaskInstance: matches_links.get_rugby_pass_match_data 2021-04-22T10:00:00+00:00 [queued]>
[2021-05-16 21:03:53,163] {taskinstance.py:877} INFO - Dependencies all met for <TaskInstance: matches_links.get_rugby_pass_match_data 2021-04-22T10:00:00+00:00 [queued]>
[2021-05-16 21:03:53,163] {taskinstance.py:1068} INFO - 
--------------------------------------------------------------------------------
[2021-05-16 21:03:53,164] {taskinstance.py:1069} INFO - Starting attempt 1 of 2
[2021-05-16 21:03:53,164] {taskinstance.py:1070} INFO - 
--------------------------------------------------------------------------------
[2021-05-16 21:03:53,168] {taskinstance.py:1089} INFO - Executing <Task(PythonOperator): get_rugby_pass_match_data> on 2021-04-22T10:00:00+00:00
[2021-05-16 21:03:53,169] {standard_task_runner.py:52} INFO - Started process 53997 to run task
[2021-05-16 21:03:53,175] {standard_task_runner.py:76} INFO - Running: ['airflow', 'tasks', 'run', 'matches_links', 'get_rugby_pass_match_data', '2021-04-22T10:00:00+00:00', '--job-id', '9', '--pool', 'default_pool', '--raw', '--subdir', 'DAGS_FOLDER/matches_links/matches_links.py', '--cfg-path', '/var/folders/tp/ft4rfkmn1kz3dyw8hlfz1dxw0000gn/T/tmp6bm7m8h9', '--error-file', '/var/folders/tp/ft4rfkmn1kz3dyw8hlfz1dxw0000gn/T/tmpygbfiq6e']
[2021-05-16 21:03:53,177] {standard_task_runner.py:77} INFO - Job 9: Subtask get_rugby_pass_match_data
[2021-05-16 21:03:53,205] {logging_mixin.py:104} INFO - Running <TaskInstance: matches_links.get_rugby_pass_match_data 2021-04-22T10:00:00+00:00 [running]> on host Henrys-MacBook-Pro.local
[2021-05-16 21:03:53,227] {taskinstance.py:1281} INFO - Exporting the following env vars:
AIRFLOW_CTX_DAG_OWNER=me
AIRFLOW_CTX_DAG_ID=matches_links
AIRFLOW_CTX_TASK_ID=get_rugby_pass_match_data
AIRFLOW_CTX_EXECUTION_DATE=2021-04-22T10:00:00+00:00
AIRFLOW_CTX_DAG_RUN_ID=backfill__2021-04-22T10:00:00+00:00
[2021-05-16 21:03:53,228] {taskinstance.py:1482} ERROR - Task failed with exception
Traceback (most recent call last):
  File "/Users/harry/.local/share/virtualenvs/rugby_data_project_airflow-d2RAFQI6/lib/python3.8/site-packages/airflow/models/taskinstance.py", line 1138, in _run_raw_task
    self._prepare_and_execute_task_with_callbacks(context, task)
  File "/Users/harry/.local/share/virtualenvs/rugby_data_project_airflow-d2RAFQI6/lib/python3.8/site-packages/airflow/models/taskinstance.py", line 1311, in _prepare_and_execute_task_with_callbacks
    result = self._execute_task(context, task_copy)
  File "/Users/harry/.local/share/virtualenvs/rugby_data_project_airflow-d2RAFQI6/lib/python3.8/site-packages/airflow/models/taskinstance.py", line 1341, in _execute_task
    result = task_copy.execute(context=context)
  File "/Users/harry/.local/share/virtualenvs/rugby_data_project_airflow-d2RAFQI6/lib/python3.8/site-packages/airflow/operators/python.py", line 112, in execute
    context.update(self.op_kwargs)
ValueError: dictionary update sequence element #0 has length 1; 2 is required
[2021-05-16 21:03:53,230] {taskinstance.py:1525} INFO - Marking task as UP_FOR_RETRY. dag_id=matches_links, task_id=get_rugby_pass_match_data, execution_date=20210422T100000, start_date=20210516T200353, end_date=20210516T200353
[2021-05-16 21:03:53,274] {local_task_job.py:146} INFO - Task exited with return code 1
[2021-05-16 21:11:20,839] {taskinstance.py:877} INFO - Dependencies all met for <TaskInstance: matches_links.get_rugby_pass_match_data 2021-04-22T10:00:00+00:00 [queued]>
[2021-05-16 21:11:20,844] {taskinstance.py:877} INFO - Dependencies all met for <TaskInstance: matches_links.get_rugby_pass_match_data 2021-04-22T10:00:00+00:00 [queued]>
[2021-05-16 21:11:20,844] {taskinstance.py:1068} INFO - 
--------------------------------------------------------------------------------
[2021-05-16 21:11:20,844] {taskinstance.py:1069} INFO - Starting attempt 1 of 2
[2021-05-16 21:11:20,844] {taskinstance.py:1070} INFO - 
--------------------------------------------------------------------------------
[2021-05-16 21:11:20,849] {taskinstance.py:1089} INFO - Executing <Task(PythonOperator): get_rugby_pass_match_data> on 2021-04-22T10:00:00+00:00
[2021-05-16 21:11:20,851] {standard_task_runner.py:52} INFO - Started process 59407 to run task
[2021-05-16 21:11:20,859] {standard_task_runner.py:76} INFO - Running: ['airflow', 'tasks', 'run', 'matches_links', 'get_rugby_pass_match_data', '2021-04-22T10:00:00+00:00', '--job-id', '10', '--pool', 'default_pool', '--raw', '--subdir', 'DAGS_FOLDER/matches_links/matches_links.py', '--cfg-path', '/var/folders/tp/ft4rfkmn1kz3dyw8hlfz1dxw0000gn/T/tmp9dwi3imx', '--error-file', '/var/folders/tp/ft4rfkmn1kz3dyw8hlfz1dxw0000gn/T/tmphfit99bn']
[2021-05-16 21:11:20,861] {standard_task_runner.py:77} INFO - Job 10: Subtask get_rugby_pass_match_data
[2021-05-16 21:11:20,891] {logging_mixin.py:104} INFO - Running <TaskInstance: matches_links.get_rugby_pass_match_data 2021-04-22T10:00:00+00:00 [running]> on host Henrys-MacBook-Pro.local
[2021-05-16 21:11:20,916] {taskinstance.py:1281} INFO - Exporting the following env vars:
AIRFLOW_CTX_DAG_OWNER=me
AIRFLOW_CTX_DAG_ID=matches_links
AIRFLOW_CTX_TASK_ID=get_rugby_pass_match_data
AIRFLOW_CTX_EXECUTION_DATE=2021-04-22T10:00:00+00:00
AIRFLOW_CTX_DAG_RUN_ID=backfill__2021-04-22T10:00:00+00:00
[2021-05-16 21:11:20,917] {taskinstance.py:1482} ERROR - Task failed with exception
Traceback (most recent call last):
  File "/Users/harry/.local/share/virtualenvs/rugby_data_project_airflow-d2RAFQI6/lib/python3.8/site-packages/airflow/models/taskinstance.py", line 1138, in _run_raw_task
    self._prepare_and_execute_task_with_callbacks(context, task)
  File "/Users/harry/.local/share/virtualenvs/rugby_data_project_airflow-d2RAFQI6/lib/python3.8/site-packages/airflow/models/taskinstance.py", line 1311, in _prepare_and_execute_task_with_callbacks
    result = self._execute_task(context, task_copy)
  File "/Users/harry/.local/share/virtualenvs/rugby_data_project_airflow-d2RAFQI6/lib/python3.8/site-packages/airflow/models/taskinstance.py", line 1341, in _execute_task
    result = task_copy.execute(context=context)
  File "/Users/harry/.local/share/virtualenvs/rugby_data_project_airflow-d2RAFQI6/lib/python3.8/site-packages/airflow/operators/python.py", line 112, in execute
    context.update(self.op_kwargs)
ValueError: dictionary update sequence element #0 has length 1; 2 is required
[2021-05-16 21:11:20,919] {taskinstance.py:1525} INFO - Marking task as UP_FOR_RETRY. dag_id=matches_links, task_id=get_rugby_pass_match_data, execution_date=20210422T100000, start_date=20210516T201120, end_date=20210516T201120
[2021-05-16 21:11:20,958] {local_task_job.py:146} INFO - Task exited with return code 1
[2021-05-16 21:12:50,924] {taskinstance.py:877} INFO - Dependencies all met for <TaskInstance: matches_links.get_rugby_pass_match_data 2021-04-22T10:00:00+00:00 [queued]>
[2021-05-16 21:12:50,930] {taskinstance.py:877} INFO - Dependencies all met for <TaskInstance: matches_links.get_rugby_pass_match_data 2021-04-22T10:00:00+00:00 [queued]>
[2021-05-16 21:12:50,930] {taskinstance.py:1068} INFO - 
--------------------------------------------------------------------------------
[2021-05-16 21:12:50,930] {taskinstance.py:1069} INFO - Starting attempt 1 of 2
[2021-05-16 21:12:50,930] {taskinstance.py:1070} INFO - 
--------------------------------------------------------------------------------
[2021-05-16 21:12:50,935] {taskinstance.py:1089} INFO - Executing <Task(PythonOperator): get_rugby_pass_match_data> on 2021-04-22T10:00:00+00:00
[2021-05-16 21:12:50,937] {standard_task_runner.py:52} INFO - Started process 60539 to run task
[2021-05-16 21:12:50,942] {standard_task_runner.py:76} INFO - Running: ['airflow', 'tasks', 'run', 'matches_links', 'get_rugby_pass_match_data', '2021-04-22T10:00:00+00:00', '--job-id', '3', '--pool', 'default_pool', '--raw', '--subdir', 'DAGS_FOLDER/matches_links/matches_links.py', '--cfg-path', '/var/folders/tp/ft4rfkmn1kz3dyw8hlfz1dxw0000gn/T/tmpjy_77aoz', '--error-file', '/var/folders/tp/ft4rfkmn1kz3dyw8hlfz1dxw0000gn/T/tmp6c1zuche']
[2021-05-16 21:12:50,944] {standard_task_runner.py:77} INFO - Job 3: Subtask get_rugby_pass_match_data
[2021-05-16 21:12:50,972] {logging_mixin.py:104} INFO - Running <TaskInstance: matches_links.get_rugby_pass_match_data 2021-04-22T10:00:00+00:00 [running]> on host 1.0.0.127.in-addr.arpa
[2021-05-16 21:12:50,993] {taskinstance.py:1281} INFO - Exporting the following env vars:
AIRFLOW_CTX_DAG_OWNER=me
AIRFLOW_CTX_DAG_ID=matches_links
AIRFLOW_CTX_TASK_ID=get_rugby_pass_match_data
AIRFLOW_CTX_EXECUTION_DATE=2021-04-22T10:00:00+00:00
AIRFLOW_CTX_DAG_RUN_ID=backfill__2021-04-22T10:00:00+00:00
[2021-05-16 21:12:50,993] {taskinstance.py:1482} ERROR - Task failed with exception
Traceback (most recent call last):
  File "/Users/harry/.local/share/virtualenvs/rugby_data_project_airflow-d2RAFQI6/lib/python3.8/site-packages/airflow/models/taskinstance.py", line 1138, in _run_raw_task
    self._prepare_and_execute_task_with_callbacks(context, task)
  File "/Users/harry/.local/share/virtualenvs/rugby_data_project_airflow-d2RAFQI6/lib/python3.8/site-packages/airflow/models/taskinstance.py", line 1311, in _prepare_and_execute_task_with_callbacks
    result = self._execute_task(context, task_copy)
  File "/Users/harry/.local/share/virtualenvs/rugby_data_project_airflow-d2RAFQI6/lib/python3.8/site-packages/airflow/models/taskinstance.py", line 1341, in _execute_task
    result = task_copy.execute(context=context)
  File "/Users/harry/.local/share/virtualenvs/rugby_data_project_airflow-d2RAFQI6/lib/python3.8/site-packages/airflow/operators/python.py", line 112, in execute
    context.update(self.op_kwargs)
ValueError: dictionary update sequence element #0 has length 1; 2 is required
[2021-05-16 21:12:50,995] {taskinstance.py:1525} INFO - Marking task as UP_FOR_RETRY. dag_id=matches_links, task_id=get_rugby_pass_match_data, execution_date=20210422T100000, start_date=20210516T201250, end_date=20210516T201250
[2021-05-16 21:12:51,047] {local_task_job.py:146} INFO - Task exited with return code 1
[2021-05-16 21:16:23,277] {taskinstance.py:877} INFO - Dependencies all met for <TaskInstance: matches_links.get_rugby_pass_match_data 2021-04-22T10:00:00+00:00 [queued]>
[2021-05-16 21:16:23,282] {taskinstance.py:877} INFO - Dependencies all met for <TaskInstance: matches_links.get_rugby_pass_match_data 2021-04-22T10:00:00+00:00 [queued]>
[2021-05-16 21:16:23,282] {taskinstance.py:1068} INFO - 
--------------------------------------------------------------------------------
[2021-05-16 21:16:23,282] {taskinstance.py:1069} INFO - Starting attempt 1 of 2
[2021-05-16 21:16:23,282] {taskinstance.py:1070} INFO - 
--------------------------------------------------------------------------------
[2021-05-16 21:16:23,286] {taskinstance.py:1089} INFO - Executing <Task(BashOperator): get_rugby_pass_match_data> on 2021-04-22T10:00:00+00:00
[2021-05-16 21:16:23,288] {standard_task_runner.py:52} INFO - Started process 62983 to run task
[2021-05-16 21:16:23,295] {standard_task_runner.py:76} INFO - Running: ['airflow', 'tasks', 'run', 'matches_links', 'get_rugby_pass_match_data', '2021-04-22T10:00:00+00:00', '--job-id', '4', '--pool', 'default_pool', '--raw', '--subdir', 'DAGS_FOLDER/matches_links/matches_links.py', '--cfg-path', '/var/folders/tp/ft4rfkmn1kz3dyw8hlfz1dxw0000gn/T/tmpqc73e7cx', '--error-file', '/var/folders/tp/ft4rfkmn1kz3dyw8hlfz1dxw0000gn/T/tmpek6m9nb3']
[2021-05-16 21:16:23,297] {standard_task_runner.py:77} INFO - Job 4: Subtask get_rugby_pass_match_data
[2021-05-16 21:16:23,328] {logging_mixin.py:104} INFO - Running <TaskInstance: matches_links.get_rugby_pass_match_data 2021-04-22T10:00:00+00:00 [running]> on host 1.0.0.127.in-addr.arpa
[2021-05-16 21:16:23,353] {taskinstance.py:1281} INFO - Exporting the following env vars:
AIRFLOW_CTX_DAG_OWNER=me
AIRFLOW_CTX_DAG_ID=matches_links
AIRFLOW_CTX_TASK_ID=get_rugby_pass_match_data
AIRFLOW_CTX_EXECUTION_DATE=2021-04-22T10:00:00+00:00
AIRFLOW_CTX_DAG_RUN_ID=backfill__2021-04-22T10:00:00+00:00
[2021-05-16 21:16:23,354] {bash.py:135} INFO - Tmp dir root location: 
 /var/folders/tp/ft4rfkmn1kz3dyw8hlfz1dxw0000gn/T
[2021-05-16 21:16:23,355] {bash.py:158} INFO - Running command: Rscript /Users/harry/rugby_data_project_airflow/R/scripts/create_matches_table.R
[2021-05-16 21:16:23,362] {bash.py:169} INFO - Output:
[2021-05-16 21:16:23,535] {bash.py:173} INFO - Error in file(filename, "r", encoding = encoding) :
[2021-05-16 21:16:23,536] {bash.py:173} INFO -   cannot open the connection
[2021-05-16 21:16:23,536] {bash.py:173} INFO - Calls: source -> file
[2021-05-16 21:16:23,536] {bash.py:173} INFO - In addition: Warning message:
[2021-05-16 21:16:23,537] {bash.py:173} INFO - In file(filename, "r", encoding = encoding) :
[2021-05-16 21:16:23,537] {bash.py:173} INFO -   cannot open file 'R/variables/data_variables.R': No such file or directory
[2021-05-16 21:16:23,537] {bash.py:173} INFO - Execution halted
[2021-05-16 21:16:23,547] {bash.py:177} INFO - Command exited with return code 1
[2021-05-16 21:16:23,553] {taskinstance.py:1482} ERROR - Task failed with exception
Traceback (most recent call last):
  File "/Users/harry/.local/share/virtualenvs/rugby_data_project_airflow-d2RAFQI6/lib/python3.8/site-packages/airflow/models/taskinstance.py", line 1138, in _run_raw_task
    self._prepare_and_execute_task_with_callbacks(context, task)
  File "/Users/harry/.local/share/virtualenvs/rugby_data_project_airflow-d2RAFQI6/lib/python3.8/site-packages/airflow/models/taskinstance.py", line 1311, in _prepare_and_execute_task_with_callbacks
    result = self._execute_task(context, task_copy)
  File "/Users/harry/.local/share/virtualenvs/rugby_data_project_airflow-d2RAFQI6/lib/python3.8/site-packages/airflow/models/taskinstance.py", line 1341, in _execute_task
    result = task_copy.execute(context=context)
  File "/Users/harry/.local/share/virtualenvs/rugby_data_project_airflow-d2RAFQI6/lib/python3.8/site-packages/airflow/operators/bash.py", line 180, in execute
    raise AirflowException('Bash command failed. The command returned a non-zero exit code.')
airflow.exceptions.AirflowException: Bash command failed. The command returned a non-zero exit code.
[2021-05-16 21:16:23,555] {taskinstance.py:1525} INFO - Marking task as UP_FOR_RETRY. dag_id=matches_links, task_id=get_rugby_pass_match_data, execution_date=20210422T100000, start_date=20210516T201623, end_date=20210516T201623
[2021-05-16 21:16:23,599] {local_task_job.py:146} INFO - Task exited with return code 1
[2021-05-16 21:20:07,493] {taskinstance.py:877} INFO - Dependencies all met for <TaskInstance: matches_links.get_rugby_pass_match_data 2021-04-22T10:00:00+00:00 [queued]>
[2021-05-16 21:20:07,499] {taskinstance.py:877} INFO - Dependencies all met for <TaskInstance: matches_links.get_rugby_pass_match_data 2021-04-22T10:00:00+00:00 [queued]>
[2021-05-16 21:20:07,499] {taskinstance.py:1068} INFO - 
--------------------------------------------------------------------------------
[2021-05-16 21:20:07,499] {taskinstance.py:1069} INFO - Starting attempt 1 of 2
[2021-05-16 21:20:07,499] {taskinstance.py:1070} INFO - 
--------------------------------------------------------------------------------
[2021-05-16 21:20:07,504] {taskinstance.py:1089} INFO - Executing <Task(PythonOperator): get_rugby_pass_match_data> on 2021-04-22T10:00:00+00:00
[2021-05-16 21:20:07,507] {standard_task_runner.py:52} INFO - Started process 65613 to run task
[2021-05-16 21:20:07,515] {standard_task_runner.py:76} INFO - Running: ['airflow', 'tasks', 'run', 'matches_links', 'get_rugby_pass_match_data', '2021-04-22T10:00:00+00:00', '--job-id', '3', '--pool', 'default_pool', '--raw', '--subdir', 'DAGS_FOLDER/matches_links/matches_links.py', '--cfg-path', '/var/folders/tp/ft4rfkmn1kz3dyw8hlfz1dxw0000gn/T/tmpqhr7jw6p', '--error-file', '/var/folders/tp/ft4rfkmn1kz3dyw8hlfz1dxw0000gn/T/tmpx6prni42']
[2021-05-16 21:20:07,518] {standard_task_runner.py:77} INFO - Job 3: Subtask get_rugby_pass_match_data
[2021-05-16 21:20:07,551] {logging_mixin.py:104} INFO - Running <TaskInstance: matches_links.get_rugby_pass_match_data 2021-04-22T10:00:00+00:00 [running]> on host 1.0.0.127.in-addr.arpa
[2021-05-16 21:20:07,576] {taskinstance.py:1281} INFO - Exporting the following env vars:
AIRFLOW_CTX_DAG_OWNER=me
AIRFLOW_CTX_DAG_ID=matches_links
AIRFLOW_CTX_TASK_ID=get_rugby_pass_match_data
AIRFLOW_CTX_EXECUTION_DATE=2021-04-22T10:00:00+00:00
AIRFLOW_CTX_DAG_RUN_ID=backfill__2021-04-22T10:00:00+00:00
[2021-05-16 21:20:07,577] {taskinstance.py:1482} ERROR - Task failed with exception
Traceback (most recent call last):
  File "/Users/harry/.local/share/virtualenvs/rugby_data_project_airflow-d2RAFQI6/lib/python3.8/site-packages/airflow/models/taskinstance.py", line 1138, in _run_raw_task
    self._prepare_and_execute_task_with_callbacks(context, task)
  File "/Users/harry/.local/share/virtualenvs/rugby_data_project_airflow-d2RAFQI6/lib/python3.8/site-packages/airflow/models/taskinstance.py", line 1311, in _prepare_and_execute_task_with_callbacks
    result = self._execute_task(context, task_copy)
  File "/Users/harry/.local/share/virtualenvs/rugby_data_project_airflow-d2RAFQI6/lib/python3.8/site-packages/airflow/models/taskinstance.py", line 1341, in _execute_task
    result = task_copy.execute(context=context)
  File "/Users/harry/.local/share/virtualenvs/rugby_data_project_airflow-d2RAFQI6/lib/python3.8/site-packages/airflow/operators/python.py", line 112, in execute
    context.update(self.op_kwargs)
ValueError: dictionary update sequence element #0 has length 1; 2 is required
[2021-05-16 21:20:07,579] {taskinstance.py:1525} INFO - Marking task as UP_FOR_RETRY. dag_id=matches_links, task_id=get_rugby_pass_match_data, execution_date=20210422T100000, start_date=20210516T202007, end_date=20210516T202007
[2021-05-16 21:20:07,606] {local_task_job.py:146} INFO - Task exited with return code 1
