[2021-05-16 20:37:38,573] {taskinstance.py:877} INFO - Dependencies all met for <TaskInstance: matches_links.get_rugby_pass_match_data 2021-04-22T10:00:00+00:00 [queued]>
[2021-05-16 20:37:38,579] {taskinstance.py:877} INFO - Dependencies all met for <TaskInstance: matches_links.get_rugby_pass_match_data 2021-04-22T10:00:00+00:00 [queued]>
[2021-05-16 20:37:38,579] {taskinstance.py:1068} INFO - 
--------------------------------------------------------------------------------
[2021-05-16 20:37:38,579] {taskinstance.py:1069} INFO - Starting attempt 2 of 2
[2021-05-16 20:37:38,579] {taskinstance.py:1070} INFO - 
--------------------------------------------------------------------------------
[2021-05-16 20:37:38,586] {taskinstance.py:1089} INFO - Executing <Task(PythonOperator): get_rugby_pass_match_data> on 2021-04-22T10:00:00+00:00
[2021-05-16 20:37:38,587] {standard_task_runner.py:52} INFO - Started process 36264 to run task
[2021-05-16 20:37:38,595] {standard_task_runner.py:76} INFO - Running: ['airflow', 'tasks', 'run', 'matches_links', 'get_rugby_pass_match_data', '2021-04-22T10:00:00+00:00', '--job-id', '4', '--pool', 'default_pool', '--raw', '--subdir', 'DAGS_FOLDER/matches_links/matches_links.py', '--cfg-path', '/var/folders/tp/ft4rfkmn1kz3dyw8hlfz1dxw0000gn/T/tmp3j08dvjb', '--error-file', '/var/folders/tp/ft4rfkmn1kz3dyw8hlfz1dxw0000gn/T/tmpyrbtndgg']
[2021-05-16 20:37:38,596] {standard_task_runner.py:77} INFO - Job 4: Subtask get_rugby_pass_match_data
[2021-05-16 20:37:38,627] {logging_mixin.py:104} INFO - Running <TaskInstance: matches_links.get_rugby_pass_match_data 2021-04-22T10:00:00+00:00 [running]> on host 1.0.0.127.in-addr.arpa
[2021-05-16 20:37:38,648] {taskinstance.py:1281} INFO - Exporting the following env vars:
AIRFLOW_CTX_DAG_OWNER=me
AIRFLOW_CTX_DAG_ID=matches_links
AIRFLOW_CTX_TASK_ID=get_rugby_pass_match_data
AIRFLOW_CTX_EXECUTION_DATE=2021-04-22T10:00:00+00:00
AIRFLOW_CTX_DAG_RUN_ID=backfill__2021-04-22T10:00:00+00:00
[2021-05-16 20:37:38,655] {callbacks.py:123} WARNING - R[write to console]: Error in file(filename, "r", encoding = encoding) : 
  cannot open the connection

[2021-05-16 20:37:38,656] {callbacks.py:123} WARNING - R[write to console]: In addition: 
[2021-05-16 20:37:38,656] {callbacks.py:123} WARNING - R[write to console]: Warning message:

[2021-05-16 20:37:38,656] {callbacks.py:123} WARNING - R[write to console]: In file(filename, "r", encoding = encoding) :
[2021-05-16 20:37:38,656] {callbacks.py:123} WARNING - R[write to console]: 
 
[2021-05-16 20:37:38,657] {callbacks.py:123} WARNING - R[write to console]:  cannot open file 'create_matches_table.R': No such file or directory

[2021-05-16 20:37:38,661] {taskinstance.py:1482} ERROR - Task failed with exception
Traceback (most recent call last):
  File "/Users/harry/.local/share/virtualenvs/rugby_data_project_airflow-d2RAFQI6/lib/python3.8/site-packages/airflow/models/taskinstance.py", line 1138, in _run_raw_task
    self._prepare_and_execute_task_with_callbacks(context, task)
  File "/Users/harry/.local/share/virtualenvs/rugby_data_project_airflow-d2RAFQI6/lib/python3.8/site-packages/airflow/models/taskinstance.py", line 1311, in _prepare_and_execute_task_with_callbacks
    result = self._execute_task(context, task_copy)
  File "/Users/harry/.local/share/virtualenvs/rugby_data_project_airflow-d2RAFQI6/lib/python3.8/site-packages/airflow/models/taskinstance.py", line 1341, in _execute_task
    result = task_copy.execute(context=context)
  File "/Users/harry/.local/share/virtualenvs/rugby_data_project_airflow-d2RAFQI6/lib/python3.8/site-packages/airflow/operators/python.py", line 117, in execute
    return_value = self.execute_callable()
  File "/Users/harry/.local/share/virtualenvs/rugby_data_project_airflow-d2RAFQI6/lib/python3.8/site-packages/airflow/operators/python.py", line 128, in execute_callable
    return self.python_callable(*self.op_args, **self.op_kwargs)
  File "/Users/harry/rugby_data_project_airflow/airflow/dags/matches_links/matches_links.py", line 11, in run_r
    r['source']("create_matches_table.R")
  File "/Users/harry/.local/share/virtualenvs/rugby_data_project_airflow-d2RAFQI6/lib/python3.8/site-packages/rpy2/robjects/functions.py", line 198, in __call__
    return (super(SignatureTranslatedFunction, self)
  File "/Users/harry/.local/share/virtualenvs/rugby_data_project_airflow-d2RAFQI6/lib/python3.8/site-packages/rpy2/robjects/functions.py", line 125, in __call__
    res = super(Function, self).__call__(*new_args, **new_kwargs)
  File "/Users/harry/.local/share/virtualenvs/rugby_data_project_airflow-d2RAFQI6/lib/python3.8/site-packages/rpy2/rinterface_lib/conversion.py", line 45, in _
    cdata = function(*args, **kwargs)
  File "/Users/harry/.local/share/virtualenvs/rugby_data_project_airflow-d2RAFQI6/lib/python3.8/site-packages/rpy2/rinterface.py", line 680, in __call__
    raise embedded.RRuntimeError(_rinterface._geterrmessage())
rpy2.rinterface_lib.embedded.RRuntimeError: Error in file(filename, "r", encoding = encoding) : 
  cannot open the connection

[2021-05-16 20:37:38,670] {taskinstance.py:1525} INFO - Marking task as FAILED. dag_id=matches_links, task_id=get_rugby_pass_match_data, execution_date=20210422T100000, start_date=20210516T193738, end_date=20210516T193738
[2021-05-16 20:37:38,687] {local_task_job.py:146} INFO - Task exited with return code 1
[2021-05-16 21:02:46,581] {taskinstance.py:877} INFO - Dependencies all met for <TaskInstance: matches_links.get_rugby_pass_match_data 2021-04-22T10:00:00+00:00 [queued]>
[2021-05-16 21:02:46,586] {taskinstance.py:877} INFO - Dependencies all met for <TaskInstance: matches_links.get_rugby_pass_match_data 2021-04-22T10:00:00+00:00 [queued]>
[2021-05-16 21:02:46,587] {taskinstance.py:1068} INFO - 
--------------------------------------------------------------------------------
[2021-05-16 21:02:46,587] {taskinstance.py:1069} INFO - Starting attempt 2 of 2
[2021-05-16 21:02:46,587] {taskinstance.py:1070} INFO - 
--------------------------------------------------------------------------------
[2021-05-16 21:02:46,591] {taskinstance.py:1089} INFO - Executing <Task(PythonOperator): get_rugby_pass_match_data> on 2021-04-22T10:00:00+00:00
[2021-05-16 21:02:46,593] {standard_task_runner.py:52} INFO - Started process 53115 to run task
[2021-05-16 21:02:46,598] {standard_task_runner.py:76} INFO - Running: ['airflow', 'tasks', 'run', 'matches_links', 'get_rugby_pass_match_data', '2021-04-22T10:00:00+00:00', '--job-id', '10', '--pool', 'default_pool', '--raw', '--subdir', 'DAGS_FOLDER/matches_links/matches_links.py', '--cfg-path', '/var/folders/tp/ft4rfkmn1kz3dyw8hlfz1dxw0000gn/T/tmpv24yf0j4', '--error-file', '/var/folders/tp/ft4rfkmn1kz3dyw8hlfz1dxw0000gn/T/tmpuq8_azzf']
[2021-05-16 21:02:46,600] {standard_task_runner.py:77} INFO - Job 10: Subtask get_rugby_pass_match_data
[2021-05-16 21:02:46,629] {logging_mixin.py:104} INFO - Running <TaskInstance: matches_links.get_rugby_pass_match_data 2021-04-22T10:00:00+00:00 [running]> on host Henrys-MacBook-Pro.local
[2021-05-16 21:02:46,649] {taskinstance.py:1281} INFO - Exporting the following env vars:
AIRFLOW_CTX_DAG_OWNER=me
AIRFLOW_CTX_DAG_ID=matches_links
AIRFLOW_CTX_TASK_ID=get_rugby_pass_match_data
AIRFLOW_CTX_EXECUTION_DATE=2021-04-22T10:00:00+00:00
AIRFLOW_CTX_DAG_RUN_ID=backfill__2021-04-22T10:00:00+00:00
[2021-05-16 21:02:46,650] {taskinstance.py:1482} ERROR - Task failed with exception
Traceback (most recent call last):
  File "/Users/harry/.local/share/virtualenvs/rugby_data_project_airflow-d2RAFQI6/lib/python3.8/site-packages/airflow/models/taskinstance.py", line 1138, in _run_raw_task
    self._prepare_and_execute_task_with_callbacks(context, task)
  File "/Users/harry/.local/share/virtualenvs/rugby_data_project_airflow-d2RAFQI6/lib/python3.8/site-packages/airflow/models/taskinstance.py", line 1311, in _prepare_and_execute_task_with_callbacks
    result = self._execute_task(context, task_copy)
  File "/Users/harry/.local/share/virtualenvs/rugby_data_project_airflow-d2RAFQI6/lib/python3.8/site-packages/airflow/models/taskinstance.py", line 1341, in _execute_task
    result = task_copy.execute(context=context)
  File "/Users/harry/.local/share/virtualenvs/rugby_data_project_airflow-d2RAFQI6/lib/python3.8/site-packages/airflow/operators/python.py", line 112, in execute
    context.update(self.op_kwargs)
ValueError: dictionary update sequence element #0 has length 1; 2 is required
[2021-05-16 21:02:46,652] {taskinstance.py:1525} INFO - Marking task as FAILED. dag_id=matches_links, task_id=get_rugby_pass_match_data, execution_date=20210422T100000, start_date=20210516T200246, end_date=20210516T200246
[2021-05-16 21:02:46,694] {local_task_job.py:146} INFO - Task exited with return code 1
[2021-05-16 21:10:23,227] {taskinstance.py:877} INFO - Dependencies all met for <TaskInstance: matches_links.get_rugby_pass_match_data 2021-04-22T10:00:00+00:00 [queued]>
[2021-05-16 21:10:23,232] {taskinstance.py:877} INFO - Dependencies all met for <TaskInstance: matches_links.get_rugby_pass_match_data 2021-04-22T10:00:00+00:00 [queued]>
[2021-05-16 21:10:23,232] {taskinstance.py:1068} INFO - 
--------------------------------------------------------------------------------
[2021-05-16 21:10:23,232] {taskinstance.py:1069} INFO - Starting attempt 2 of 3
[2021-05-16 21:10:23,232] {taskinstance.py:1070} INFO - 
--------------------------------------------------------------------------------
[2021-05-16 21:10:23,236] {taskinstance.py:1089} INFO - Executing <Task(PythonOperator): get_rugby_pass_match_data> on 2021-04-22T10:00:00+00:00
[2021-05-16 21:10:23,239] {standard_task_runner.py:52} INFO - Started process 58723 to run task
[2021-05-16 21:10:23,244] {standard_task_runner.py:76} INFO - Running: ['airflow', 'tasks', 'run', 'matches_links', 'get_rugby_pass_match_data', '2021-04-22T10:00:00+00:00', '--job-id', '11', '--pool', 'default_pool', '--raw', '--subdir', 'DAGS_FOLDER/matches_links/matches_links.py', '--cfg-path', '/var/folders/tp/ft4rfkmn1kz3dyw8hlfz1dxw0000gn/T/tmppu52l25o', '--error-file', '/var/folders/tp/ft4rfkmn1kz3dyw8hlfz1dxw0000gn/T/tmp54eym38k']
[2021-05-16 21:10:23,246] {standard_task_runner.py:77} INFO - Job 11: Subtask get_rugby_pass_match_data
[2021-05-16 21:10:23,274] {logging_mixin.py:104} INFO - Running <TaskInstance: matches_links.get_rugby_pass_match_data 2021-04-22T10:00:00+00:00 [running]> on host 1.0.0.127.in-addr.arpa
[2021-05-16 21:10:23,295] {taskinstance.py:1281} INFO - Exporting the following env vars:
AIRFLOW_CTX_DAG_OWNER=me
AIRFLOW_CTX_DAG_ID=matches_links
AIRFLOW_CTX_TASK_ID=get_rugby_pass_match_data
AIRFLOW_CTX_EXECUTION_DATE=2021-04-22T10:00:00+00:00
AIRFLOW_CTX_DAG_RUN_ID=backfill__2021-04-22T10:00:00+00:00
[2021-05-16 21:10:23,296] {taskinstance.py:1482} ERROR - Task failed with exception
Traceback (most recent call last):
  File "/Users/harry/.local/share/virtualenvs/rugby_data_project_airflow-d2RAFQI6/lib/python3.8/site-packages/airflow/models/taskinstance.py", line 1138, in _run_raw_task
    self._prepare_and_execute_task_with_callbacks(context, task)
  File "/Users/harry/.local/share/virtualenvs/rugby_data_project_airflow-d2RAFQI6/lib/python3.8/site-packages/airflow/models/taskinstance.py", line 1311, in _prepare_and_execute_task_with_callbacks
    result = self._execute_task(context, task_copy)
  File "/Users/harry/.local/share/virtualenvs/rugby_data_project_airflow-d2RAFQI6/lib/python3.8/site-packages/airflow/models/taskinstance.py", line 1341, in _execute_task
    result = task_copy.execute(context=context)
  File "/Users/harry/.local/share/virtualenvs/rugby_data_project_airflow-d2RAFQI6/lib/python3.8/site-packages/airflow/operators/python.py", line 112, in execute
    context.update(self.op_kwargs)
ValueError: dictionary update sequence element #0 has length 1; 2 is required
[2021-05-16 21:10:23,297] {taskinstance.py:1525} INFO - Marking task as UP_FOR_RETRY. dag_id=matches_links, task_id=get_rugby_pass_match_data, execution_date=20210422T100000, start_date=20210516T201023, end_date=20210516T201023
[2021-05-16 21:10:23,346] {local_task_job.py:146} INFO - Task exited with return code 1
