[2021-05-16 20:42:50,698] {taskinstance.py:877} INFO - Dependencies all met for <TaskInstance: matches_links.get_rugby_pass_match_data 2021-04-22T10:00:00+00:00 [queued]>
[2021-05-16 20:42:50,702] {taskinstance.py:877} INFO - Dependencies all met for <TaskInstance: matches_links.get_rugby_pass_match_data 2021-04-22T10:00:00+00:00 [queued]>
[2021-05-16 20:42:50,702] {taskinstance.py:1068} INFO - 
--------------------------------------------------------------------------------
[2021-05-16 20:42:50,702] {taskinstance.py:1069} INFO - Starting attempt 3 of 4
[2021-05-16 20:42:50,702] {taskinstance.py:1070} INFO - 
--------------------------------------------------------------------------------
[2021-05-16 20:42:50,708] {taskinstance.py:1089} INFO - Executing <Task(PythonOperator): get_rugby_pass_match_data> on 2021-04-22T10:00:00+00:00
[2021-05-16 20:42:50,710] {standard_task_runner.py:52} INFO - Started process 40198 to run task
[2021-05-16 20:42:50,717] {standard_task_runner.py:76} INFO - Running: ['airflow', 'tasks', 'run', 'matches_links', 'get_rugby_pass_match_data', '2021-04-22T10:00:00+00:00', '--job-id', '6', '--pool', 'default_pool', '--raw', '--subdir', 'DAGS_FOLDER/matches_links/matches_links.py', '--cfg-path', '/var/folders/tp/ft4rfkmn1kz3dyw8hlfz1dxw0000gn/T/tmpvyhw_wa8', '--error-file', '/var/folders/tp/ft4rfkmn1kz3dyw8hlfz1dxw0000gn/T/tmp8_2dp3jv']
[2021-05-16 20:42:50,719] {standard_task_runner.py:77} INFO - Job 6: Subtask get_rugby_pass_match_data
[2021-05-16 20:42:50,749] {logging_mixin.py:104} INFO - Running <TaskInstance: matches_links.get_rugby_pass_match_data 2021-04-22T10:00:00+00:00 [running]> on host 1.0.0.127.in-addr.arpa
[2021-05-16 20:42:50,768] {taskinstance.py:1281} INFO - Exporting the following env vars:
AIRFLOW_CTX_DAG_OWNER=me
AIRFLOW_CTX_DAG_ID=matches_links
AIRFLOW_CTX_TASK_ID=get_rugby_pass_match_data
AIRFLOW_CTX_EXECUTION_DATE=2021-04-22T10:00:00+00:00
AIRFLOW_CTX_DAG_RUN_ID=backfill__2021-04-22T10:00:00+00:00
[2021-05-16 20:42:50,777] {callbacks.py:123} WARNING - R[write to console]: Error in (function (file, local = FALSE, echo = verbose, print.eval = echo,  : 
  airflow/dags/matches_links/matches_links.py:1:8: unexpected symbol
1: import datetime
           ^

[2021-05-16 20:42:50,780] {taskinstance.py:1482} ERROR - Task failed with exception
Traceback (most recent call last):
  File "/Users/harry/.local/share/virtualenvs/rugby_data_project_airflow-d2RAFQI6/lib/python3.8/site-packages/airflow/models/taskinstance.py", line 1138, in _run_raw_task
    self._prepare_and_execute_task_with_callbacks(context, task)
  File "/Users/harry/.local/share/virtualenvs/rugby_data_project_airflow-d2RAFQI6/lib/python3.8/site-packages/airflow/models/taskinstance.py", line 1311, in _prepare_and_execute_task_with_callbacks
    result = self._execute_task(context, task_copy)
  File "/Users/harry/.local/share/virtualenvs/rugby_data_project_airflow-d2RAFQI6/lib/python3.8/site-packages/airflow/models/taskinstance.py", line 1341, in _execute_task
    result = task_copy.execute(context=context)
  File "/Users/harry/.local/share/virtualenvs/rugby_data_project_airflow-d2RAFQI6/lib/python3.8/site-packages/airflow/operators/python.py", line 117, in execute
    return_value = self.execute_callable()
  File "/Users/harry/.local/share/virtualenvs/rugby_data_project_airflow-d2RAFQI6/lib/python3.8/site-packages/airflow/operators/python.py", line 128, in execute_callable
    return self.python_callable(*self.op_args, **self.op_kwargs)
  File "/Users/harry/rugby_data_project_airflow/airflow/dags/matches_links/matches_links.py", line 11, in run_r
    r['source']("airflow/dags/matches_links/matches_links.py")
  File "/Users/harry/.local/share/virtualenvs/rugby_data_project_airflow-d2RAFQI6/lib/python3.8/site-packages/rpy2/robjects/functions.py", line 198, in __call__
    return (super(SignatureTranslatedFunction, self)
  File "/Users/harry/.local/share/virtualenvs/rugby_data_project_airflow-d2RAFQI6/lib/python3.8/site-packages/rpy2/robjects/functions.py", line 125, in __call__
    res = super(Function, self).__call__(*new_args, **new_kwargs)
  File "/Users/harry/.local/share/virtualenvs/rugby_data_project_airflow-d2RAFQI6/lib/python3.8/site-packages/rpy2/rinterface_lib/conversion.py", line 45, in _
    cdata = function(*args, **kwargs)
  File "/Users/harry/.local/share/virtualenvs/rugby_data_project_airflow-d2RAFQI6/lib/python3.8/site-packages/rpy2/rinterface.py", line 680, in __call__
    raise embedded.RRuntimeError(_rinterface._geterrmessage())
rpy2.rinterface_lib.embedded.RRuntimeError: Error in (function (file, local = FALSE, echo = verbose, print.eval = echo,  : 
  airflow/dags/matches_links/matches_links.py:1:8: unexpected symbol
1: import datetime
           ^

[2021-05-16 20:42:50,788] {taskinstance.py:1525} INFO - Marking task as UP_FOR_RETRY. dag_id=matches_links, task_id=get_rugby_pass_match_data, execution_date=20210422T100000, start_date=20210516T194250, end_date=20210516T194250
[2021-05-16 20:42:50,818] {local_task_job.py:146} INFO - Task exited with return code 1
[2021-05-16 21:03:08,853] {taskinstance.py:877} INFO - Dependencies all met for <TaskInstance: matches_links.get_rugby_pass_match_data 2021-04-22T10:00:00+00:00 [queued]>
[2021-05-16 21:03:08,860] {taskinstance.py:877} INFO - Dependencies all met for <TaskInstance: matches_links.get_rugby_pass_match_data 2021-04-22T10:00:00+00:00 [queued]>
[2021-05-16 21:03:08,860] {taskinstance.py:1068} INFO - 
--------------------------------------------------------------------------------
[2021-05-16 21:03:08,860] {taskinstance.py:1069} INFO - Starting attempt 3 of 4
[2021-05-16 21:03:08,860] {taskinstance.py:1070} INFO - 
--------------------------------------------------------------------------------
[2021-05-16 21:03:08,865] {taskinstance.py:1089} INFO - Executing <Task(PythonOperator): get_rugby_pass_match_data> on 2021-04-22T10:00:00+00:00
[2021-05-16 21:03:08,866] {standard_task_runner.py:52} INFO - Started process 53424 to run task
[2021-05-16 21:03:08,872] {standard_task_runner.py:76} INFO - Running: ['airflow', 'tasks', 'run', 'matches_links', 'get_rugby_pass_match_data', '2021-04-22T10:00:00+00:00', '--job-id', '12', '--pool', 'default_pool', '--raw', '--subdir', 'DAGS_FOLDER/matches_links/matches_links.py', '--cfg-path', '/var/folders/tp/ft4rfkmn1kz3dyw8hlfz1dxw0000gn/T/tmphara6pc2', '--error-file', '/var/folders/tp/ft4rfkmn1kz3dyw8hlfz1dxw0000gn/T/tmphob7gqdm']
[2021-05-16 21:03:08,873] {standard_task_runner.py:77} INFO - Job 12: Subtask get_rugby_pass_match_data
[2021-05-16 21:03:08,907] {logging_mixin.py:104} INFO - Running <TaskInstance: matches_links.get_rugby_pass_match_data 2021-04-22T10:00:00+00:00 [running]> on host Henrys-MacBook-Pro.local
[2021-05-16 21:03:08,925] {taskinstance.py:1281} INFO - Exporting the following env vars:
AIRFLOW_CTX_DAG_OWNER=me
AIRFLOW_CTX_DAG_ID=matches_links
AIRFLOW_CTX_TASK_ID=get_rugby_pass_match_data
AIRFLOW_CTX_EXECUTION_DATE=2021-04-22T10:00:00+00:00
AIRFLOW_CTX_DAG_RUN_ID=backfill__2021-04-22T10:00:00+00:00
[2021-05-16 21:03:08,926] {taskinstance.py:1482} ERROR - Task failed with exception
Traceback (most recent call last):
  File "/Users/harry/.local/share/virtualenvs/rugby_data_project_airflow-d2RAFQI6/lib/python3.8/site-packages/airflow/models/taskinstance.py", line 1138, in _run_raw_task
    self._prepare_and_execute_task_with_callbacks(context, task)
  File "/Users/harry/.local/share/virtualenvs/rugby_data_project_airflow-d2RAFQI6/lib/python3.8/site-packages/airflow/models/taskinstance.py", line 1311, in _prepare_and_execute_task_with_callbacks
    result = self._execute_task(context, task_copy)
  File "/Users/harry/.local/share/virtualenvs/rugby_data_project_airflow-d2RAFQI6/lib/python3.8/site-packages/airflow/models/taskinstance.py", line 1341, in _execute_task
    result = task_copy.execute(context=context)
  File "/Users/harry/.local/share/virtualenvs/rugby_data_project_airflow-d2RAFQI6/lib/python3.8/site-packages/airflow/operators/python.py", line 112, in execute
    context.update(self.op_kwargs)
ValueError: dictionary update sequence element #0 has length 1; 2 is required
[2021-05-16 21:03:08,928] {taskinstance.py:1525} INFO - Marking task as UP_FOR_RETRY. dag_id=matches_links, task_id=get_rugby_pass_match_data, execution_date=20210422T100000, start_date=20210516T200308, end_date=20210516T200308
[2021-05-16 21:03:08,969] {local_task_job.py:146} INFO - Task exited with return code 1
