[2021-05-16 20:17:39,100] {taskinstance.py:877} INFO - Dependencies all met for <TaskInstance: matches_links.get_rugby_pass_match_data 2017-06-16T00:00:00+00:00 [queued]>
[2021-05-16 20:17:39,114] {taskinstance.py:877} INFO - Dependencies all met for <TaskInstance: matches_links.get_rugby_pass_match_data 2017-06-16T00:00:00+00:00 [queued]>
[2021-05-16 20:17:39,114] {taskinstance.py:1068} INFO - 
--------------------------------------------------------------------------------
[2021-05-16 20:17:39,114] {taskinstance.py:1069} INFO - Starting attempt 1 of 2
[2021-05-16 20:17:39,114] {taskinstance.py:1070} INFO - 
--------------------------------------------------------------------------------
[2021-05-16 20:17:39,126] {taskinstance.py:1089} INFO - Executing <Task(PythonOperator): get_rugby_pass_match_data> on 2017-06-16T00:00:00+00:00
[2021-05-16 20:17:39,134] {standard_task_runner.py:52} INFO - Started process 22913 to run task
[2021-05-16 20:17:39,142] {standard_task_runner.py:76} INFO - Running: ['airflow', 'tasks', 'run', 'matches_links', 'get_rugby_pass_match_data', '2017-06-16T00:00:00+00:00', '--job-id', '5275', '--pool', 'default_pool', '--raw', '--subdir', 'DAGS_FOLDER/matches_links.py', '--cfg-path', '/var/folders/tp/ft4rfkmn1kz3dyw8hlfz1dxw0000gn/T/tmpd56vbmjz', '--error-file', '/var/folders/tp/ft4rfkmn1kz3dyw8hlfz1dxw0000gn/T/tmpxlylxgb1']
[2021-05-16 20:17:39,144] {standard_task_runner.py:77} INFO - Job 5275: Subtask get_rugby_pass_match_data
[2021-05-16 20:17:39,175] {logging_mixin.py:104} INFO - Running <TaskInstance: matches_links.get_rugby_pass_match_data 2017-06-16T00:00:00+00:00 [running]> on host 1.0.0.127.in-addr.arpa
[2021-05-16 20:17:39,198] {taskinstance.py:1281} INFO - Exporting the following env vars:
AIRFLOW_CTX_DAG_OWNER=me
AIRFLOW_CTX_DAG_ID=matches_links
AIRFLOW_CTX_TASK_ID=get_rugby_pass_match_data
AIRFLOW_CTX_EXECUTION_DATE=2017-06-16T00:00:00+00:00
AIRFLOW_CTX_DAG_RUN_ID=scheduled__2017-06-16T00:00:00+00:00
[2021-05-16 20:17:39,198] {taskinstance.py:1482} ERROR - Task failed with exception
Traceback (most recent call last):
  File "/Users/harry/.local/share/virtualenvs/rugby_data_project_airflow-d2RAFQI6/lib/python3.8/site-packages/airflow/models/taskinstance.py", line 1138, in _run_raw_task
    self._prepare_and_execute_task_with_callbacks(context, task)
  File "/Users/harry/.local/share/virtualenvs/rugby_data_project_airflow-d2RAFQI6/lib/python3.8/site-packages/airflow/models/taskinstance.py", line 1311, in _prepare_and_execute_task_with_callbacks
    result = self._execute_task(context, task_copy)
  File "/Users/harry/.local/share/virtualenvs/rugby_data_project_airflow-d2RAFQI6/lib/python3.8/site-packages/airflow/models/taskinstance.py", line 1341, in _execute_task
    result = task_copy.execute(context=context)
  File "/Users/harry/.local/share/virtualenvs/rugby_data_project_airflow-d2RAFQI6/lib/python3.8/site-packages/airflow/operators/python.py", line 112, in execute
    context.update(self.op_kwargs)
ValueError: dictionary update sequence element #0 has length 1; 2 is required
[2021-05-16 20:17:39,202] {taskinstance.py:1525} INFO - Marking task as UP_FOR_RETRY. dag_id=matches_links, task_id=get_rugby_pass_match_data, execution_date=20170616T000000, start_date=20210516T191739, end_date=20210516T191739
[2021-05-16 20:17:39,236] {local_task_job.py:146} INFO - Task exited with return code 1
