[2021-05-16 21:20:54,392] {taskinstance.py:877} INFO - Dependencies all met for <TaskInstance: matches_links.get_rugby_pass_match_data 2021-04-23T10:00:00+00:00 [queued]>
[2021-05-16 21:20:54,398] {taskinstance.py:877} INFO - Dependencies all met for <TaskInstance: matches_links.get_rugby_pass_match_data 2021-04-23T10:00:00+00:00 [queued]>
[2021-05-16 21:20:54,398] {taskinstance.py:1068} INFO - 
--------------------------------------------------------------------------------
[2021-05-16 21:20:54,398] {taskinstance.py:1069} INFO - Starting attempt 1 of 2
[2021-05-16 21:20:54,398] {taskinstance.py:1070} INFO - 
--------------------------------------------------------------------------------
[2021-05-16 21:20:54,403] {taskinstance.py:1089} INFO - Executing <Task(PythonOperator): get_rugby_pass_match_data> on 2021-04-23T10:00:00+00:00
[2021-05-16 21:20:54,405] {standard_task_runner.py:52} INFO - Started process 66182 to run task
[2021-05-16 21:20:54,413] {standard_task_runner.py:76} INFO - Running: ['airflow', 'tasks', 'run', 'matches_links', 'get_rugby_pass_match_data', '2021-04-23T10:00:00+00:00', '--job-id', '5', '--pool', 'default_pool', '--raw', '--subdir', 'DAGS_FOLDER/matches_links/matches_links.py', '--cfg-path', '/var/folders/tp/ft4rfkmn1kz3dyw8hlfz1dxw0000gn/T/tmplwndxay0', '--error-file', '/var/folders/tp/ft4rfkmn1kz3dyw8hlfz1dxw0000gn/T/tmpvsj7dw47']
[2021-05-16 21:20:54,415] {standard_task_runner.py:77} INFO - Job 5: Subtask get_rugby_pass_match_data
[2021-05-16 21:20:54,448] {logging_mixin.py:104} INFO - Running <TaskInstance: matches_links.get_rugby_pass_match_data 2021-04-23T10:00:00+00:00 [running]> on host Henrys-MacBook-Pro.local
[2021-05-16 21:20:54,471] {taskinstance.py:1281} INFO - Exporting the following env vars:
AIRFLOW_CTX_DAG_OWNER=me
AIRFLOW_CTX_DAG_ID=matches_links
AIRFLOW_CTX_TASK_ID=get_rugby_pass_match_data
AIRFLOW_CTX_EXECUTION_DATE=2021-04-23T10:00:00+00:00
AIRFLOW_CTX_DAG_RUN_ID=backfill__2021-04-23T10:00:00+00:00
[2021-05-16 21:20:54,471] {taskinstance.py:1482} ERROR - Task failed with exception
Traceback (most recent call last):
  File "/Users/harry/.local/share/virtualenvs/rugby_data_project_airflow-d2RAFQI6/lib/python3.8/site-packages/airflow/models/taskinstance.py", line 1138, in _run_raw_task
    self._prepare_and_execute_task_with_callbacks(context, task)
  File "/Users/harry/.local/share/virtualenvs/rugby_data_project_airflow-d2RAFQI6/lib/python3.8/site-packages/airflow/models/taskinstance.py", line 1311, in _prepare_and_execute_task_with_callbacks
    result = self._execute_task(context, task_copy)
  File "/Users/harry/.local/share/virtualenvs/rugby_data_project_airflow-d2RAFQI6/lib/python3.8/site-packages/airflow/models/taskinstance.py", line 1341, in _execute_task
    result = task_copy.execute(context=context)
  File "/Users/harry/.local/share/virtualenvs/rugby_data_project_airflow-d2RAFQI6/lib/python3.8/site-packages/airflow/operators/python.py", line 112, in execute
    context.update(self.op_kwargs)
ValueError: dictionary update sequence element #0 has length 1; 2 is required
[2021-05-16 21:20:54,475] {taskinstance.py:1525} INFO - Marking task as UP_FOR_RETRY. dag_id=matches_links, task_id=get_rugby_pass_match_data, execution_date=20210423T100000, start_date=20210516T202054, end_date=20210516T202054
[2021-05-16 21:20:54,511] {local_task_job.py:146} INFO - Task exited with return code 1
